<mujoco model="tidybot scene">
  <compiler angle="radian" meshdir="../assets/"/>

  <option impratio="10" integrator="implicitfast" cone="elliptic"/>

  <visual>
    <global azimuth="120" elevation="-20"/>
    <headlight diffuse="0.6 0.6 0.6" specular="0 0 0"/>
    <rgba haze="0.15 0.25 0.35 1"/>
  </visual>

  <statistic meansize="0.05" extent="1" center="0.25 0 0.6"/>

  <default>
    <site size="0.001 0.005 0.005" group="4" rgba="0.5 0.5 0.5 0.3"/>
    <default class="base">
      <default class="base/visual">
        <geom type="mesh" contype="0" conaffinity="0" group="2"/>
      </default>
      <default class="base/collision">
        <geom type="mesh" group="3"/>
      </default>
    </default>
    <default class="gen3">
      <default class="gen3/visual">
        <geom type="mesh" contype="0" conaffinity="0" group="2" rgba="0.75294 0.75294 0.75294 1"/>
      </default>
      <default class="gen3/collision">
        <geom type="mesh" group="3"/>
      </default>
      <default class="large_actuator">
        <general forcerange="-105 105" biastype="affine" gainprm="2000" biasprm="0 -2000 -100"/>
      </default>
      <default class="small_actuator">
        <general forcerange="-52 52" biastype="affine" gainprm="500" biasprm="0 -500 -50"/>
      </default>
    </default>
    <default class="2f85">
      <mesh scale="0.001 0.001 0.001"/>
      <general biastype="affine"/>
      <default class="driver">
        <joint solreflimit="0.005" solimplimit="0.95 0.99" range="0 0.8" armature="0.005" damping="0.1"/>
      </default>
      <default class="follower">
        <joint solreflimit="0.005" solimplimit="0.95 0.99" range="-0.872664 0.872664" armature="0.001"/>
      </default>
      <default class="spring_link">
        <joint springref="2.62" stiffness="0.05" range="-0.296706 0.8" armature="0.001" damping="0.00125"/>
      </default>
      <default class="coupler">
        <joint solreflimit="0.005" solimplimit="0.95 0.99" range="-1.57 0" armature="0.001"/>
      </default>
      <default class="2f85/visual">
        <geom type="mesh" contype="0" conaffinity="0" group="2"/>
      </default>
      <default class="2f85/collision">
        <geom type="mesh" group="3"/>
        <default class="pad_box1">
          <geom size="0.011 0.004 0.009375" type="box" priority="1" friction="0.7" solref="0.004" solimp="0.95 0.99" rgba="0.55 0.55 0.55 1"/>
        </default>
        <default class="pad_box2">
          <geom size="0.011 0.004 0.009375" type="box" priority="1" friction="0.6" solref="0.004" solimp="0.95 0.99" rgba="0.45 0.45 0.45 1"/>
        </default>
      </default>
    </default>
  </default>

  <asset>
    <texture type="skybox" builtin="gradient" rgb1="0.3 0.5 0.7" rgb2="0 0 0" width="512" height="3072"/>
    <texture type="2d" name="groundplane" builtin="checker" mark="edge" rgb1="0.2 0.3 0.4" rgb2="0.1 0.2 0.3" markrgb="0.8 0.8 0.8" width="300" height="300"/>
    <material name="black" rgba="0.113725 0.113725 0.101961 1"/>
    <material name="gray" rgba="0.627451 0.65098 0.647059 1"/>
    <material name="dark_gray" rgba="0.352941 0.376471 0.372549 1"/>
    <material name="metal" rgba="0.58 0.58 0.58 1"/>
    <material name="silicone" rgba="0.1882 0.1882 0.1882 1"/>
    <material name="2f85/gray" rgba="0.4627 0.4627 0.4627 1"/>
    <material name="2f85/black" rgba="0.149 0.149 0.149 1"/>
    <material name="groundplane" texture="groundplane" texuniform="true" texrepeat="5 5"/>
    <mesh name="bumper" file="base/bumper.stl"/>
    <mesh name="bottom_plate" file="base/bottom_plate.stl"/>
    <mesh name="body" file="base/body.stl"/>
    <mesh name="top_plate" file="base/top_plate.stl"/>
    <mesh name="arm_plate" file="base/arm_plate.stl"/>
    <mesh name="gen3/base_link" file="gen3/base_link.stl"/>
    <mesh name="shoulder_link" file="gen3/shoulder_link.stl"/>
    <mesh name="half_arm_1_link" file="gen3/half_arm_1_link.stl"/>
    <mesh name="half_arm_2_link" file="gen3/half_arm_2_link.stl"/>
    <mesh name="forearm_link" file="gen3/forearm_link.stl"/>
    <mesh name="spherical_wrist_1_link" file="gen3/spherical_wrist_1_link.stl"/>
    <mesh name="spherical_wrist_2_link" file="gen3/spherical_wrist_2_link.stl"/>
    <mesh name="bracelet_with_vision_link" file="gen3/bracelet_with_vision_link.stl"/>
    <mesh name="base" class="2f85" file="2f85/base.stl"/>
    <mesh name="driver" class="2f85" file="2f85/driver.stl"/>
    <mesh name="coupler" class="2f85" file="2f85/coupler.stl"/>
    <mesh name="follower" class="2f85" file="2f85/follower.stl"/>
    <mesh name="pad" class="2f85" file="2f85/pad.stl"/>
    <mesh name="silicone_pad" class="2f85" file="2f85/silicone_pad.stl"/>
    <mesh name="spring_link" class="2f85" file="2f85/spring_link.stl"/>
  </asset>

  <worldbody>
    <geom name="floor" size="0 0 0.05" type="plane" material="groundplane"/>
    <light pos="0 0 1.5" dir="0 0 -1" directional="true"/>
    <body name="base_link">
      <inertial pos="0 0 0.035" mass="60" diaginertia="0.001 0.001 0.001"/>
      <joint name="joint_x" pos="0 0 0" axis="1 0 0" type="slide"/>
      <joint name="joint_y" pos="0 0 0" axis="0 1 0" type="slide"/>
      <joint name="joint_th" pos="0 0 0" axis="0 0 1"/>
      <geom class="base/visual" material="black" mesh="bumper"/>
      <geom class="base/visual" material="dark_gray" mesh="bottom_plate"/>
      <geom class="base/visual" material="gray" mesh="body"/>
      <geom class="base/visual" material="dark_gray" mesh="top_plate"/>
      <geom class="base/visual" material="gray" mesh="arm_plate"/>
      <geom class="base/collision" mesh="bumper"/>
      <geom class="base/collision" mesh="bottom_plate"/>
      <geom class="base/collision" mesh="body"/>
      <geom class="base/collision" mesh="top_plate"/>
      <geom class="base/collision" mesh="arm_plate"/>
      <camera name="base" pos="0.2525 0 0.335" quat="0.653281 0.270598 -0.270598 -0.653281" resolution="640 360" fovy="52.2338"/>
      <body name="gen3/base_link" pos="0 0 0.335">
        <inertial pos="-0.000648 -0.000166 0.084487" quat="0.999294 0.00139618 -0.0118387 0.035636" mass="1.697" diaginertia="0.00462407 0.00449437 0.00207755"/>
        <geom class="gen3/visual" mesh="gen3/base_link"/>
        <geom class="gen3/collision" mesh="gen3/base_link"/>
        <body name="shoulder_link" pos="0 0 0.15643" quat="0 1 0 0">
          <inertial pos="-2.3e-05 -0.010364 -0.07336" quat="0.707051 0.0451246 -0.0453544 0.704263" mass="1.3773" diaginertia="0.00488868 0.00457 0.00135132"/>
          <joint name="joint_1" pos="0 0 0" axis="0 0 1"/>
          <geom class="gen3/visual" mesh="shoulder_link"/>
          <geom class="gen3/collision" mesh="shoulder_link"/>
          <body name="half_arm_1_link" pos="0 0.005375 -0.12838" quat="0.707107 0.707107 0 0">
            <inertial pos="-4.4e-05 -0.09958 -0.013278" quat="0.482348 0.516286 -0.516862 0.483366" mass="1.1636" diaginertia="0.0113017 0.011088 0.00102532"/>
            <joint name="joint_2" pos="0 0 0" axis="0 0 1" range="-2.24 2.24"/>
            <geom class="gen3/visual" mesh="half_arm_1_link"/>
            <geom class="gen3/collision" mesh="half_arm_1_link"/>
            <body name="half_arm_2_link" pos="0 -0.21038 -0.006375" quat="0.707107 -0.707107 0 0">
              <inertial pos="-4.4e-05 -0.006641 -0.117892" quat="0.706144 0.0213722 -0.0209128 0.707437" mass="1.1636" diaginertia="0.0111633 0.010932 0.00100671"/>
              <joint name="joint_3" pos="0 0 0" axis="0 0 1"/>
              <geom class="gen3/visual" mesh="half_arm_2_link"/>
              <geom class="gen3/collision" mesh="half_arm_2_link"/>
              <body name="forearm_link" pos="0 0.006375 -0.21038" quat="0.707107 0.707107 0 0">
                <inertial pos="-1.8e-05 -0.075478 -0.015006" quat="0.483678 0.515961 -0.515859 0.483455" mass="0.9302" diaginertia="0.00834839 0.008147 0.000598606"/>
                <joint name="joint_4" pos="0 0 0" axis="0 0 1" range="-2.57 2.57"/>
                <geom class="gen3/visual" mesh="forearm_link"/>
                <geom class="gen3/collision" mesh="forearm_link"/>
                <body name="spherical_wrist_1_link" pos="0 -0.20843 -0.006375" quat="0.707107 -0.707107 0 0">
                  <inertial pos="1e-06 -0.009432 -0.063883" quat="0.703558 0.0707492 -0.0707492 0.703558" mass="0.6781" diaginertia="0.00165901 0.001596 0.000346988"/>
                  <joint name="joint_5" pos="0 0 0" axis="0 0 1"/>
                  <geom class="gen3/visual" mesh="spherical_wrist_1_link"/>
                  <geom class="gen3/collision" mesh="spherical_wrist_1_link"/>
                  <body name="spherical_wrist_2_link" pos="0 0.00017505 -0.10593" quat="0.707107 0.707107 0 0">
                    <inertial pos="1e-06 -0.045483 -0.00965" quat="0.44426 0.550121 -0.550121 0.44426" mass="0.6781" diaginertia="0.00170087 0.001641 0.00035013"/>
                    <joint name="joint_6" pos="0 0 0" axis="0 0 1" range="-2.09 2.09"/>
                    <geom class="gen3/visual" mesh="spherical_wrist_2_link"/>
                    <geom class="gen3/collision" mesh="spherical_wrist_2_link"/>
                    <body name="bracelet_link" pos="0 -0.10593 -0.00017505" quat="0.707107 -0.707107 0 0">
                      <inertial pos="0.000281 0.011402 -0.029798" quat="0.394358 0.596779 -0.577293 0.393789" mass="0.5" diaginertia="0.000657336 0.000587019 0.000320645"/>
                      <joint name="joint_7" pos="0 0 0" axis="0 0 1"/>
                      <geom class="gen3/visual" mesh="bracelet_with_vision_link"/>
                      <geom class="gen3/collision" mesh="bracelet_with_vision_link"/>
                      <site name="pinch_site" pos="0 0 -0.181525" quat="0 1 0 0"/>
                      <camera name="wrist" pos="0 -0.05639 -0.058475" quat="0 0 0 1" resolution="640 480" fovy="41.8379"/>
                      <body name="base" childclass="2f85" pos="0 0 -0.0614904" quat="0 -0.707107 0.707107 0">
                        <inertial pos="0 -2.70394e-05 0.0354675" quat="0.999999 -0.00152849 0 0" mass="0.777441" diaginertia="0.000260285 0.000225381 0.000152708"/>
                        <geom class="2f85/visual" material="2f85/black" mesh="base"/>
                        <geom class="2f85/collision" mesh="base"/>
                        <body name="right_driver" pos="0 0.0306011 0.054904">
                          <inertial pos="2.96931e-12 0.0177547 0.00107314" quat="0.681301 0.732003 0 0" mass="0.00899563" diaginertia="1.72352e-06 1.60906e-06 3.22006e-07"/>
                          <joint name="right_driver_joint" class="driver" pos="0 0 0" axis="1 0 0"/>
                          <geom class="2f85/visual" material="2f85/gray" mesh="driver"/>
                          <geom class="2f85/collision" mesh="driver"/>
                          <body name="right_coupler" pos="0 0.0315 -0.0041">
                            <inertial pos="0 0.00301209 0.0232175" quat="0.705636 -0.0455904 0.0455904 0.705636" mass="0.0140974" diaginertia="4.16206e-06 3.52216e-06 8.88131e-07"/>
                            <joint name="right_coupler_joint" class="coupler" pos="0 0 0" axis="1 0 0"/>
                            <geom class="2f85/visual" material="2f85/black" mesh="coupler"/>
                            <geom class="2f85/collision" mesh="coupler"/>
                          </body>
                        </body>
                        <body name="right_spring_link" pos="0 0.0132 0.0609">
                          <inertial pos="-8.65005e-09 0.0181624 0.0212658" quat="0.663403 -0.244737 0.244737 0.663403" mass="0.0221642" diaginertia="8.96853e-06 6.71733e-06 2.63931e-06"/>
                          <joint name="right_spring_link_joint" class="spring_link" pos="0 0 0" axis="1 0 0" springref="2.62"/>
                          <geom class="2f85/visual" material="2f85/black" mesh="spring_link"/>
                          <geom class="2f85/collision" mesh="spring_link"/>
                          <body name="right_follower" pos="0 0.055 0.0375">
                            <inertial pos="0 -0.011046 0.0124786" quat="0.986437 0.164143 0 0" mass="0.0125222" diaginertia="2.67415e-06 2.4559e-06 6.02031e-07"/>
                            <joint name="right_follower_joint" class="follower" pos="0 -0.018 0.0065" axis="1 0 0"/>
                            <geom class="2f85/visual" material="2f85/black" mesh="follower"/>
                            <geom class="2f85/collision" mesh="follower"/>
                            <body name="right_pad" pos="0 -0.0189 0.01352">
                              <inertial pos="0 -0.0025 0.0185" quat="0.707107 0 0 0.707107" mass="0.0035" diaginertia="4.73958e-07 3.64583e-07 1.23958e-07"/>
                              <geom name="right_pad1" class="pad_box1" pos="0 -0.0026 0.028125" mass="0"/>
                              <geom name="right_pad2" class="pad_box2" pos="0 -0.0026 0.009375" mass="0"/>
                              <geom class="2f85/visual" mesh="pad"/>
                              <body name="right_silicone_pad">
                                <geom class="2f85/visual" material="2f85/black" mesh="silicone_pad"/>
                              </body>
                            </body>
                          </body>
                        </body>
                        <body name="left_driver" pos="0 -0.0306011 0.054904" quat="0 0 0 1">
                          <inertial pos="0 0.0177547 0.00107314" quat="0.681301 0.732003 0 0" mass="0.00899563" diaginertia="1.72352e-06 1.60906e-06 3.22006e-07"/>
                          <joint name="left_driver_joint" class="driver" pos="0 0 0" axis="1 0 0"/>
                          <geom class="2f85/visual" material="2f85/gray" mesh="driver"/>
                          <geom class="2f85/collision" mesh="driver"/>
                          <body name="left_coupler" pos="0 0.0315 -0.0041">
                            <inertial pos="0 0.00301209 0.0232175" quat="0.705636 -0.0455904 0.0455904 0.705636" mass="0.0140974" diaginertia="4.16206e-06 3.52216e-06 8.88131e-07"/>
                            <joint name="left_coupler_joint" class="coupler" pos="0 0 0" axis="1 0 0"/>
                            <geom class="2f85/visual" material="2f85/black" mesh="coupler"/>
                            <geom class="2f85/collision" mesh="coupler"/>
                          </body>
                        </body>
                        <body name="left_spring_link" pos="0 -0.0132 0.0609" quat="0 0 0 1">
                          <inertial pos="-8.65005e-09 0.0181624 0.0212658" quat="0.663403 -0.244737 0.244737 0.663403" mass="0.0221642" diaginertia="8.96853e-06 6.71733e-06 2.63931e-06"/>
                          <joint name="left_spring_link_joint" class="spring_link" pos="0 0 0" axis="1 0 0" springref="2.62"/>
                          <geom class="2f85/visual" material="2f85/black" mesh="spring_link"/>
                          <geom class="2f85/collision" mesh="spring_link"/>
                          <body name="left_follower" pos="0 0.055 0.0375">
                            <inertial pos="0 -0.011046 0.0124786" quat="0.986437 0.164143 0 0" mass="0.0125222" diaginertia="2.67415e-06 2.4559e-06 6.02031e-07"/>
                            <joint name="left_follower_joint" class="follower" pos="0 -0.018 0.0065" axis="1 0 0"/>
                            <geom class="2f85/visual" material="2f85/black" mesh="follower"/>
                            <geom class="2f85/collision" mesh="follower"/>
                            <body name="left_pad" pos="0 -0.0189 0.01352">
                              <inertial pos="0 -0.0025 0.0185" quat="0.707107 0 0 0.707107" mass="0.0035" diaginertia="4.73958e-07 3.64583e-07 1.23958e-07"/>
                              <geom name="left_pad1" class="pad_box1" pos="0 -0.0026 0.028125" mass="0"/>
                              <geom name="left_pad2" class="pad_box2" pos="0 -0.0026 0.009375" mass="0"/>
                              <geom class="2f85/visual" mesh="pad"/>
                              <body name="left_silicone_pad">
                                <geom class="2f85/visual" material="2f85/black" mesh="silicone_pad"/>
                              </body>
                            </body>
                          </body>
                        </body>
                      </body>
                    </body>
                  </body>
                </body>
              </body>
            </body>
          </body>
        </body>
      </body>
    </body>
    <body name="cube" pos="0.6 0 0.02">
      <joint type="free" limited="false" actuatorfrclimited="false"/>
      <geom size="0.02 0.02 0.02" type="box" mass="0.1" rgba="0.5 0.7 0.5 1"/>
    </body>
  </worldbody>

  <contact>
    <exclude body1="base" body2="right_driver"/>
    <exclude body1="base" body2="right_spring_link"/>
    <exclude body1="base" body2="left_driver"/>
    <exclude body1="base" body2="left_spring_link"/>
    <exclude body1="right_coupler" body2="right_follower"/>
    <exclude body1="left_coupler" body2="left_follower"/>
  </contact>

  <equality>
    <connect body1="right_follower" body2="right_coupler" anchor="0 0 0" solref="0.005" solimp="0.95 0.99"/>
    <connect body1="left_follower" body2="left_coupler" anchor="0 0 0" solref="0.005" solimp="0.95 0.99"/>
    <joint joint1="right_driver_joint" joint2="left_driver_joint" polycoef="0 1 0 0 0" solref="0.005" solimp="0.95 0.99"/>
  </equality>

  <tendon>
    <fixed name="split">
      <joint joint="right_driver_joint" coef="0.5"/>
      <joint joint="left_driver_joint" coef="0.5"/>
    </fixed>
  </tendon>

  <actuator>
    <general name="joint_x" joint="joint_x" biastype="affine" gainprm="1000000" biasprm="0 -1000000 -50000"/>
    <general name="joint_y" joint="joint_y" biastype="affine" gainprm="1000000" biasprm="0 -1000000 -50000"/>
    <general name="joint_th" joint="joint_th" biastype="affine" gainprm="50000" biasprm="0 -50000 -1000"/>
    <general name="joint_1" class="large_actuator" joint="joint_1"/>
    <general name="joint_2" class="large_actuator" joint="joint_2" ctrlrange="-2.24973 2.24973"/>
    <general name="joint_3" class="large_actuator" joint="joint_3"/>
    <general name="joint_4" class="large_actuator" joint="joint_4" ctrlrange="-2.5796 2.5796"/>
    <general name="joint_5" class="small_actuator" joint="joint_5"/>
    <general name="joint_6" class="small_actuator" joint="joint_6" ctrlrange="-2.09963 2.09963"/>
    <general name="joint_7" class="small_actuator" joint="joint_7"/>
    <general name="fingers_actuator" class="2f85" tendon="split" ctrlrange="0 255" forcerange="-5 5" gainprm="0.313725" biasprm="0 -100 -10"/>
  </actuator>
</mujoco>
