<robot name="omni_wheel" xmlns:xacro="http://wiki.ros.org/xacro">
  <!-- <xacro:include filename="$(find bobac3_description)/xacro/roller.xacro"/> -->
  <xacro:include filename="$(find bobac3_description)/xacro/custom_roller.xacro"/>
  <xacro:macro name="omni_wheel" params="prefix parent xyz rpy sim">
    <!-- <link name="${prefix}/omni_fixed_link">
      <inertial>
        <origin
          xyz="-0.00447643466609091 -5.71676574493557E-06 -3.24195721012957E-05"
          rpy="0 0 0" />
        <mass
          value="0.017517388209757" />
        <inertia
          ixx="5.93842888259313E-06"
          ixy="-7.64634360653807E-10"
          ixz="-4.33631763741016E-09"
          iyy="3.18611170928351E-06"
          iyz="1.52500974723596E-09"
          izz="3.1944913286487E-06" />
      </inertial>
      <visual>
        <origin
          xyz="0 0 0"
          rpy="0 0 0" />
        <geometry>
          <mesh
            filename="package://bobac3_description/meshes/omni_fixed_link.STL" />
        </geometry>
        <material
          name="">
          <color
            rgba="1 1 1 1" />
        </material>
      </visual>
      <collision>
        <origin
          xyz="0 0 0"
          rpy="0 0 0" />
        <geometry>
          <mesh
            filename="package://bobac3_description/meshes/omni_fixed_link.STL" />
        </geometry>
      </collision>
    </link>
    <joint name="${prefix}/wheel_fixed_joint" type="continuous">
      <parent link="${parent}" />
      <child link="${prefix}/omni_fixed_link" />
      <origin xyz="${xyz}"
        rpy="${rpy}" />
      <axis
        xyz="1 0 0" />
    </joint> -->
    <!-- <link name="${prefix}/omni_wheel_body_link">
      <inertial>
        <origin
          xyz="-1.04083408558608E-16 -2.28189299747439E-08 0.0167499999999999"
          rpy="0 0 0" />
        <mass
          value="0.119911118980826" />
        <inertia
          ixx="6.7330466638185E-05"
          ixy="-6.94020404626982E-15"
          ixz="-2.26988607624672E-11"
          iyy="6.73303716235564E-05"
          iyz="4.06331069857908E-15"
          izz="0.000109146792616575" />
      </inertial>
      <visual>
        <origin
          xyz="0 0 0"
          rpy="0 0 0" />
        <geometry>
          <mesh
            filename="package://bobac3_description/meshes/omni_wheel_body_link.STL" />
        </geometry>
        <material
          name="">
          <color
            rgba="1 1 1 1" />
        </material>
      </visual>
      <collision>
        <origin
          xyz="0 0 0"
          rpy="0 0 0" />
        <geometry>
          <mesh
            filename="package://bobac3_description/meshes/omni_wheel_body_link.STL" />
        </geometry>
      </collision>
    </link> -->
    <link name="${prefix}/omni_wheel_body_link">
      <inertial>
        <mass value="0.10"/>
        <inertia ixx="7.6e-5" ixy="0.0" ixz="0.0" iyy="7.6e-5" iyz="0.0" izz="0.000125"/>
      </inertial>
      <visual>
        <geometry>
          <cylinder radius="0.025" length="0.04"/>
        </geometry>
      </visual>
      <collision>
        <geometry>
          <cylinder radius="0.025" length="0.04"/>
        </geometry>
      </collision>
    </link>
    <joint name="${prefix}/wheel_fixed_joint" type="continuous">
      <parent link="${parent}" />
      <child link="${prefix}/omni_wheel_body_link" />
      <origin xyz="${xyz}"
        rpy="${rpy}" />
      <axis
        xyz="0 0 1" />
    </joint>
    <!-- <joint
      name="${prefix}/omni_body_joint"
      type="fixed">
      <origin
        xyz="0.01675 0 0"
        rpy="0 0 0" />
      <parent
        link="${prefix}/omni_fixed_link" />
      <child
        link="${prefix}/omni_wheel_body_link" />
      <axis
        xyz="0 0 0" />
    </joint> -->
    <xacro:if value="${sim}">
      <!-- <gazebo reference="${prefix}/omni_fixed_link">
        <material>Gazebo/Gray</material>
      </gazebo> -->
      <!-- <gazebo reference="${prefix}/omni_wheel_body_link">
        <material>Gazebo/Gray</material>
      </gazebo> -->
      
      <transmission name="${prefix}_wheel_trans">
        <type>transmission_interface/SimpleTransmission</type>
        <joint name="${prefix}/wheel_fixed_joint">
          <hardwareInterface>hardware_interface/EffortJointInterface</hardwareInterface>
        </joint>
        <actuator name="${prefix}_wheel_motor">
          <hardwareInterface>hardware_interface/EffortJointInterface</hardwareInterface>
          <mechanicalReduction>1</mechanicalReduction>
        </actuator>
      </transmission>
    </xacro:if>
    
    <xacro:custom_roller prefix="${prefix}"
      parent="omni_wheel_body_link" index="1" 
      xyz="0.03637 0.021 0.01"
      rpy="1.57079 0 0.523598 " 
      sim="${sim}"/>
    <xacro:custom_roller prefix="${prefix}"
      parent="omni_wheel_body_link" index="2" 
      xyz="0.0 0.042 0.01"
      rpy="1.57079 0 1.57079 " 
      sim="${sim}"/>
    <xacro:custom_roller prefix="${prefix}"
      parent="omni_wheel_body_link" index="3" 
      xyz="-0.03637 0.021 0.01"
      rpy="1.57079 0 2.618 " 
      sim="${sim}"/>
    <xacro:custom_roller prefix="${prefix}"
      parent="omni_wheel_body_link" index="4" 
      xyz="-0.03637 -0.021 0.01"
      rpy="1.57079 0 -2.618 " 
      sim="${sim}"/>
    <xacro:custom_roller prefix="${prefix}"
      parent="omni_wheel_body_link" index="5" 
      xyz="0.0 -0.042 0.01"
      rpy="1.57079 0 -1.57079 " 
      sim="${sim}"/>
    <xacro:custom_roller prefix="${prefix}"
      parent="omni_wheel_body_link" index="6" 
      xyz="0.03637 -0.021 0.01"
      rpy="1.57079 0 -0.523598 " 
      sim="${sim}"/>
      
    <xacro:custom_roller prefix="${prefix}"
      parent="omni_wheel_body_link" index="7" 
      xyz="0.042 0.0 -0.01"
      rpy="1.57079 0 0 " 
      sim="${sim}"/>
    <xacro:custom_roller prefix="${prefix}"
      parent="omni_wheel_body_link" index="8" 
      xyz="0.021 0.03637 -0.01"
      rpy="1.57079 0 1.04719 " 
      sim="${sim}"/>
    <xacro:custom_roller prefix="${prefix}"
      parent="omni_wheel_body_link" index="9" 
      xyz="-0.021 0.03637 -0.01"
      rpy="1.57079 0 2.09439 " 
      sim="${sim}"/>
    <xacro:custom_roller prefix="${prefix}"
      parent="omni_wheel_body_link" index="10" 
      xyz="-0.042 0.0 -0.01"
      rpy="1.57079 0 3.14159 " 
      sim="${sim}"/>
    <xacro:custom_roller prefix="${prefix}"
      parent="omni_wheel_body_link" index="11" 
      xyz="-0.021 -0.03637 -0.01"
      rpy="1.57079 0 -2.09439 " 
      sim="${sim}"/>
    <xacro:custom_roller prefix="${prefix}"
      parent="omni_wheel_body_link" index="12" 
      xyz="0.021 -0.03637 -0.01"
      rpy="1.57079 0 -1.04719 " 
      sim="${sim}"/>
    
    <!-- <xacro:omni_roller prefix="${prefix}"
      parent="omni_wheel_body_link" index="1" 
      xyz="0.00987 0 0.042"
      rpy="0 0 0" 
      sim="${sim}"/>
    <xacro:omni_roller prefix="${prefix}"
      parent="omni_wheel_body_link" index="2" 
      xyz="0.00987 0.026997 0.032174"
      rpy="-0.69813 0 0" 
      sim="${sim}"/>
    <xacro:omni_roller prefix="${prefix}"
      parent="omni_wheel_body_link" index="3" 
      xyz="0.00987 0.041362 0.0072932"
      rpy="-1.3963 0 0" 
      sim="${sim}"/>
    <xacro:omni_roller prefix="${prefix}"
      parent="omni_wheel_body_link" index="4" 
      xyz="0.00987 0.036373 -0.021"
      rpy="-2.0944 0 0" 
      sim="${sim}"/>
    <xacro:omni_roller prefix="${prefix}"
      parent="omni_wheel_body_link" index="5" 
      xyz="0.00987 0.014365 -0.039467"
      rpy="-2.7925 0 0" 
      sim="${sim}"/>
    <xacro:omni_roller prefix="${prefix}"
      parent="omni_wheel_body_link" index="6" 
      xyz="0.00987 -0.014365 -0.039467"
      rpy="2.7925 0 0" 
      sim="${sim}"/>
    <xacro:omni_roller prefix="${prefix}"
      parent="omni_wheel_body_link" index="7" 
      xyz="0.00987 -0.036373 -0.021"
      rpy="2.0944 0 0" 
      sim="${sim}"/>
    <xacro:omni_roller prefix="${prefix}"
      parent="omni_wheel_body_link" index="8" 
      xyz="0.00987 -0.041362 0.0072932"
      rpy="1.3963 0 0" 
      sim="${sim}"/>
    <xacro:omni_roller prefix="${prefix}"
      parent="omni_wheel_body_link" index="9" 
      xyz="0.00987 -0.026997 0.032174"
      rpy="0.69813 0 0" 
      sim="${sim}"/>

    <xacro:omni_roller prefix="${prefix}"
      parent="omni_wheel_body_link" index="10" 
      xyz="-0.00987 0.014365 0.039467"
      rpy="-0.34907 0 0" 
      sim="${sim}"/>
    <xacro:omni_roller prefix="${prefix}"
      parent="omni_wheel_body_link" index="11" 
      xyz="-0.00987 0.036373 0.021"
      rpy="-1.0472 0 0" 
      sim="${sim}"/>
    <xacro:omni_roller prefix="${prefix}"
      parent="omni_wheel_body_link" index="12" 
      xyz="-0.00987 0.041362 -0.0072932"
      rpy="-1.7453 0 0" 
      sim="${sim}"/>
    <xacro:omni_roller prefix="${prefix}"
      parent="omni_wheel_body_link" index="13" 
      xyz="-0.00987 0.026997 -0.032174"
      rpy="-2.4435 0 0" 
      sim="${sim}"/>
    <xacro:omni_roller prefix="${prefix}"
      parent="omni_wheel_body_link" index="14" 
      xyz="-0.00987 0 -0.042"
      rpy="3.1416 0 0" 
      sim="${sim}"/>
    <xacro:omni_roller prefix="${prefix}"
      parent="omni_wheel_body_link" index="15" 
      xyz="-0.00987 -0.026997 -0.032174"
      rpy="2.4435 0 0" 
      sim="${sim}"/>
    <xacro:omni_roller prefix="${prefix}"
      parent="omni_wheel_body_link" index="16" 
      xyz="-0.00987 -0.041362 -0.0072932"
      rpy="1.7453 0 0" 
      sim="${sim}"/>
    <xacro:omni_roller prefix="${prefix}"
      parent="omni_wheel_body_link" index="17" 
      xyz="-0.00987 -0.036373 0.021"
      rpy="1.0472 0 0" 
      sim="${sim}"/>
    <xacro:omni_roller prefix="${prefix}"
      parent="omni_wheel_body_link" index="18" 
      xyz="-0.00987 -0.014365 0.039467"
      rpy="0.34907 0 0" 
      sim="${sim}"/> -->
  </xacro:macro>
</robot>